<?xml version="1.0"?>
<robot xmlns:xacro="http://www.ros.org/wiki/xacro">

  <!-- Base Footprint -->
  <link name="base_footprint" />
  <!-- Base Link -->
  <link name="base_link">
    <visual>
      <origin xyz="0 0 -${0.1458 + 0.025}" rpy="0 0 0"/>
      <geometry>
        <cylinder length="0.05" radius="0.09" />
      </geometry>
      <material name="blue"/>
    </visual>
    <xacro:inertial_cylinder mass="0.5" length="0.05" radius="0.09">
      <origin xyz="0 0 -${0.1458 + 0.025}" rpy="0 0 0"/>
    </xacro:inertial_cylinder>
  </link>

  <!-- Counterweight -->
  <link name="counterweight">
    <visual>
      <geometry>
        <cylinder length="0.04" radius="0.07" />
      </geometry>
      <material name="black"/>
    </visual>
    <xacro:inertial_cylinder mass="1.0" length="0.04" radius="0.05">
      <origin xyz="0 0 0" rpy="0 0 0" />
    </xacro:inertial_cylinder>
  </link>

  <!-- Left Wheel -->
  <link name="left_wheel">
    <visual>
      <origin xyz="0 0 0" rpy="0 ${pi/2} 0"/>
      <geometry>
        <mesh filename="file:///$(find bb8_description)/meshes/wheel.stl" scale="0.001 0.001 0.001"/>
      </geometry>
      <material name="black"/>
    </visual>
    <collision>
      <origin xyz="0 0 0" rpy="0 ${pi/2} 0"/>
      <geometry>
        <mesh filename="file:///$(find bb8_description)/meshes/wheel.stl" scale="0.001 0.001 0.001"/>
      </geometry>
    </collision>
    <xacro:inertial_sphere mass="0.05" radius="0.076">
      <origin xyz="0 0 0" rpy="0 ${pi/2} 0"/>
    </xacro:inertial_sphere>
  </link>

  <link name="wheel_connector" >
    <visual>
      <geometry>
        <cylinder length="0.01" radius="0.01" />
      </geometry>
      <material name="blue"/>
    </visual>
    <xacro:inertial_cylinder mass="0.01" length="0.01" radius="0.01">
      <origin xyz="0 0 0" rpy="0 0 0"/>
    </xacro:inertial_cylinder>
  </link>

  <!-- Right Wheel -->
  <link name="right_wheel">
    <visual>
      <origin xyz="0 0 0" rpy="0 ${pi/2} 0"/>
      <geometry>
        <mesh filename="file:///$(find bb8_description)/meshes/wheel.stl" scale="0.001 0.001 0.001"/>
      </geometry>
      <material name="black"/>
    </visual>
    <collision>
      <origin xyz="0 0 0" rpy="0 ${pi/2} 0"/>
      <geometry>
        <mesh filename="file:///$(find bb8_description)/meshes/wheel.stl" scale="0.001 0.001 0.001"/>
      </geometry>
    </collision>
    <xacro:inertial_sphere mass="0.05" radius="0.076">
      <origin xyz="0 0 0" rpy="0 ${pi/2} 0"/>
    </xacro:inertial_sphere>
  </link>

  <!-- Joints -->
  <joint name="base_joint" type="fixed">
    <parent link="base_footprint" />
    <child link="base_link" />
    <origin xyz="0 0 0" rpy="0 0 0"/>
  </joint>

  <joint name="wheel_connector_joint" type="fixed">
    <parent link="base_link" />
    <child link="wheel_connector" />
    <origin xyz="0 0 0" rpy="0 0 ${pi/2}"/>
  </joint>

  <joint name="counterweight_joint" type="fixed">
    <parent link="base_link" />
    <child link="counterweight" />
    <origin xyz="0 0 -0.21" rpy="0 0 0"/>
  </joint>

  <joint name="left_wheel_joint" type="continuous">
    <parent link="wheel_connector"/>
    <child link="left_wheel"/>
    <origin xyz="${0.3437/2} 0 -0.1458" rpy="0 0 0"/>
    <axis xyz="1 0 0"/>
  </joint>

  <joint name="right_wheel_joint" type="continuous">
    <parent link="wheel_connector"/>
    <child link="right_wheel"/>
    <origin xyz="-${0.3437/2} 0 -0.1458" rpy="0 0 0"/>
    <axis xyz="1 0 0"/>
  </joint>


  <!-- Collision Tuning for Robot and Sphere -->
  <gazebo reference="left_wheel">
    <self_collide>true</self_collide>
    <surface>
      <contact>
        <collide_without_contact>false</collide_without_contact>
        <stiffness>1e6</stiffness>
        <damping>2e3</damping>
      </contact>
      <friction>
        <ode>
          <mu>1.0</mu> 
          <mu2>1.0</mu2>
        </ode>
      </friction>
    </surface>
  </gazebo>

  <gazebo reference="right_wheel">
    <self_collide>true</self_collide>
    <surface>
      <contact>
        <collide_without_contact>false</collide_without_contact>
        <stiffness>1e6</stiffness>
        <damping>2e3</damping>
      </contact>
      <friction>
        <ode>
          <mu>1.0</mu> 
          <mu2>1.0</mu2>
        </ode>
      </friction>
    </surface>
  </gazebo>

</robot>