<?xml version="1.0"?>
<robot xmlns:xacro="http://www.ros.org/wiki/xacro">
  <!-- Outer Sphere Link -->
  <link name="sphere_link">
    <visual>
      <geometry>
        <mesh filename="file:///$(find bb8_description)/meshes/sphere.stl" scale="0.001 0.001 0.001"/>
      </geometry>
      <material name="white_transparent">
        <color rgba="1 1 1 0.2"/>
      </material>
    </visual>
    <collision>
      <geometry>
        <mesh filename="file:///$(find bb8_description)/meshes/sphere.stl" scale="0.001 0.001 0.001"/>
      </geometry>
    </collision>
    <inertial>
      <mass value="0.5"/>
      <inertia ixx="0.2" iyy="0.2" izz="0.2" ixy="0.0" ixz="0.0" iyz="0.0"/>
    </inertial>
  </link>

  <!-- Joint to Connect Sphere and Hamster -->
  <joint name="sphere_joint" type="floating">
    <parent link="base_footprint"/>
    <child link="sphere_link"/>
    <origin xyz="0 0 0" rpy="0 0 0"/>
  </joint>

  <!-- <gazebo reference="sphere_link">
    <mu>0.5</mu>
    <mu2>0.5</mu2>
    <collision>
      <margin>0.01</margin>
    </collision>
  </gazebo> -->

  <gazebo reference="sphere_link">
    <mu>1.0</mu> 
    <mu2>1.0</mu2> 
    <collision>
      <surface>
        <contact>
          <ode>
            <min_depth>0.001</min_depth>
            </ode>
        </contact>
      </surface>
      <margin>0.01</margin>
    </collision>
   </gazebo>

</robot>